Workbook

Sheet 基本数据
A1: 阳光工匠论坛（bbs.21spv.com） 光伏/储能/运维/能源/电力资料下载 QQ群：312095674 小编微信：15995027646 | B1: 基本数据 | Q1: 其他数据
B2: 光伏部分 | G2: 储能部分 | L2: 充电桩部分 | Q2: 编号 | R2: 项目 | S2: 单位 | T2: 数据 | Y2: 每日循环次数
B3: 项目情况 | G3: 项目情况 | L3: 项目情况 | Q3: 1 | R3: 容量使用费 | S3: 元/KVA | T3: 0 | Y3: 1
B4: 编号 | C4: 项目 | D4: 单位 | E4: 数据 | G4: 编号 | H4: 项目 | I4: 单位 | J4: 数据 | L4: 编号 | M4: 项目 | N4: 单位 | O4: 数据 | Q4: 2 | R4: 无功补偿费 | S4: 元/KVA | Y4: 2
B5: 1 | C5: 装机容量 | D5: kW | E5: 0 | G5: 1 | H5: 蓄电池容量 | I5: kWh | J5: 4000 | L5: 1 | M5: 充电桩容量 | N5: kW | O5: 0 | Q5: 3 | R5: 需求响应 | S5: 元/kWh
B6: 2 | C6: 首年发电小时数 | D6: h | E6: 0 | G6: 2 | H6: 效率 | I6: % | J6: 0.9 | L6: 2 | M6: 充电电量 | N6: kWh/d | O6: 0 | Q6: 4
B7: 3 | C7: 用户电价 | D7: 元/kWh | E7: 0 | G7: 3 | H7: DOD | I7: % | J7: 0.9 | L7: 3 | M7: 充电服务费 | N7: 元/kWh | O7: 0 | Q7: 5
B8: 4 | C8: 脱硫燃煤电价 | D8: 元/kWh | E8: 0 | G8: 4 | H8: 增容 | I8: KVA | J8: 0 | L8: 投资
B9: 投资 | G9: 5 | H9: 无功补偿容量 | I9: KVA | L9: 4 | M9: 充电桩投资 | N9: 元 | O9: 0
B10: 5 | C10: 每瓦静态投资 | D10: 元/Wp | E10: 0 | G10: 电价情况 | L10: 运营
G11: 6 | H11: 非夏季峰谷价差 | I11: 元/kWh | J11: 0.6098 | L11: 5 | M11: 年均经营成本 | N11: 元
G12: 7 | H12: 非夏季峰平价差 | I12: 元/kWh | J12: 0.3194 | L12: 6 | M12: 折旧期 | N12: 年 | O12: 10
G13: 8 | H13: 夏季峰谷价差 | I13: 元/kWh | J13: 0.6098 | L13: 7 | M13: 残值率 | N13: % | O13: 0
B14: 补贴 | G14: 9 | H14: 夏季峰平价差 | I14: 元/kWh | J14: 0.3094
B15: 6 | C15: 电价补贴 | D15: 元/kWh | E15: 0 | G15: 0
B16: 运营 | G16: 10 | H16: 每WH静态投资 | I16: 元/Wh | J16: 1.8625
B17: 7 | C17: 年均经营成本 | D17: 元/Wp | E17: 0 | G17: 运营
B18: 8 | C18: 折旧期 | D18: 年 | E18: 0 | G18: 11 | H18: 年均经营成本 | I18: 元
B19: 9 | C19: 残值率 | D19: % | E19: 0 | G19: 12 | H19: 折旧期 | I19: 年 | J19: =J21/365/J22 -> 8.2191781
B20: 上网模式 | G20: 13 | H20: 残值率 | I20: % | J20: 0.3
B21: 10 | C21: 自用比例 | D21: % | E21: 1 | G21: 14 | H21: 循环寿命 | I21: 次 | J21: 6000
B22: 11 | C22: 电费折扣 | D22: % | E22: 1 | G22: 15 | H22: 每日循环次数 | I22: 次 | J22: 2
G23: 16 | H23: 电池年衰减率 | I23: % | J23: 0.015
G24: 17 | H24: 年运行天数 | I24: 天
B27: 汇总信息 | G27: 财务指标
B28: 编号 | C28: 项目 | D28: 单位 | E28: 数据 | G28: 编号 | H28: 项目 | I28: 单位 | J28: 数据
B29: 1 | C29: 总造价 | D29: 元 | E29: =J5*J16*1000 -> 7450000 | G29: 1 | H29: 回收期(税前) | I29: 年 | J29: =IRR模型!C58 -> 4.9371118
C30: 补贴 | D30: 元 | E30: =E29*0.3 -> 2235000 | G30: 2 | H30: 回收期(税后) | I30: 年 | J30: =IRR模型!C59 -> 5.1396433
B31: 2 | C31: 实际投资 | D31: 元 | E31: =E29-E30 -> 5215000 | G31: 3 | H31: 财务净现值(税前) | I31: 元 | J31: =IRR模型!C60 -> 1986381.9
B32: 3 | C32: 运营比例 | D32: % | E32: 0.01 | G32: 4 | H32: 财务净现值(税后) | I32: 元 | J32: =IRR模型!C61 -> 1583595.1
B33: 4 | C33: 资本金比例 | D33: % | E33: 1 | G33: 5 | H33: 全投资内部收益率(税前) | I33: % | J33: =IRR模型!C62 -> 0.13492246
B34: 5 | C34: 长期贷款利率 | D34: % | G34: 6 | H34: 全投资内部收益率(税后) | I34: % | J34: =IRR模型!C63 -> 0.1200652
B35: 6 | C35: 长期贷款还款期限 | D35: 年

Sheet IRR模型
B1: 分类 | C1: 0 | D1: 1 | E1: 2 | F1: 3 | G1: 4 | H1: 5 | I1: 6 | J1: 7 | K1: 8 | L1: 9 | M1: 10 | N1: 11 | O1: 12 | P1: 13 | Q1: 14 | R1: 15 | S1: 16 | T1: 17 | U1: 18 | V1: 19 | W1: 20 | X1: 21 | Y1: 22 | Z1: 23 | AA1: 24 | AB1: 25 | AC1: 合计
B2: 光伏发电量(KWH)
B3: 衰减率 | E3: 0.02 | F3: 0.007 | G3: 0.007 | H3: 0.007 | I3: 0.007 | J3: 0.007 | K3: 0.007 | L3: 0.007 | M3: 0.007 | N3: 0.007 | O3: 0.007 | P3: 0.007 | Q3: 0.007 | R3: 0.007 | S3: 0.007 | T3: 0.007 | U3: 0.007 | V3: 0.007 | W3: 0.007 | X3: 0.007 | Y3: 0.007 | Z3: 0.007 | AA3: 0.007 | AB3: 0.0067
B4: 每年发电量(KWH) | D4: =基本数据!E5*基本数据!E6 -> 0 | E4: =D4*(1-E3) -> 0 | F4: =E4*(1-F3) -> 0 | G4: =F4*(1-G3) -> 0 | H4: =G4*(1-H3) -> 0 | I4: =H4*(1-I3) -> 0 | J4: =I4*(1-J3) -> 0 | K4: =J4*(1-K3) -> 0 | L4: =K4*(1-L3) -> 0 | ... AB4: =AA4*(1-AB3) -> 0
B6: 收入
B7: 上网电价部分 | D7: =D4*(1-基本数据!$E$21)*基本数据!$E$8 -> 0 | E7: =E4*(1-基本数据!$E$21)*基本数据!$E$8 -> 0 | F7: =F4*(1-基本数据!$E$21)*基本数据!$E$8 -> 0 | G7: =G4*(1-基本数据!$E$21)*基本数据!$E$8 -> 0 | H7: =H4*(1-基本数据!$E$21)*基本数据!$E$8 -> 0 | I7: =I4*(1-基本数据!$E$21)*基本数据!$E$8 -> 0 | J7: =J4*(1-基本数据!$E$21)*基本数据!$E$8 -> 0 | K7: =K4*(1-基本数据!$E$21)*基本数据!$E$8 -> 0 | ... AB7: =AB4*(1-基本数据!$E$21)*基本数据!$E$8 -> 0
B8: 企业电价部分 | D8: =D4*基本数据!$E$21*基本数据!$E$7*基本数据!$E$22 -> 0 | E8: =E4*基本数据!$E$21*基本数据!$E$7*基本数据!$E$22 -> 0 | F8: =F4*基本数据!$E$21*基本数据!$E$7*基本数据!$E$22 -> 0 | G8: =G4*基本数据!$E$21*基本数据!$E$7*基本数据!$E$22 -> 0 | H8: =H4*基本数据!$E$21*基本数据!$E$7*基本数据!$E$22 -> 0 | I8: =I4*基本数据!$E$21*基本数据!$E$7*基本数据!$E$22 -> 0 | J8: =J4*基本数据!$E$21*基本数据!$E$7*基本数据!$E$22 -> 0 | K8: =K4*基本数据!$E$21*基本数据!$E$7*基本数据!$E$22 -> 0 | ... AB8: =AB4*基本数据!$E$21*基本数据!$E$7*基本数据!$E$22 -> 0
B9: 补贴-国家-20年 | D9: =D4*基本数据!$E$15 -> 0 | E9: =E4*基本数据!$E$15 -> 0 | F9: =F4*基本数据!$E$15 -> 0 | G9: =G4*基本数据!$E$15 -> 0 | H9: =H4*基本数据!$E$15 -> 0 | I9: =I4*基本数据!$E$15 -> 0 | J9: =J4*基本数据!$E$15 -> 0 | K9: =K4*基本数据!$E$15 -> 0 | ... AB9: =AB4*基本数据!$E$15 -> 0
B10: 峰谷电价差 | D10: =IF(D1<基本数据!$J$19,IF(基本数据!$J$22=1,(基本数据!$J$5*基本数据!$J$6*基本数据!$J$7*基本数据!$J$11*275+基本数据!$J$5*基本数据!$J$6*基本数据!$J$7*基本数据!$J$13*90),((基本数据!$J$5*基本数据!$J$6*基本数据!$J$7*基本数据!$J$11*275+基本数据!$J$5*基本数据!$J$6*基本数据!$J$7*基本数据!$J$12*275)+(基本数据!$J$5*基本数据!$J$6*基本数据!$J$7*基本数据!$J$13*90+基本数据!$J$5*基本数据!$J$6*基本数据!$J$7*基本数据!$J$14*90))),0) -> 1095955.9 | E10: =IF(D1<基本数据!$J$19,D10-D10*基本数据!$J$23,0) -> 1079516.6 | F10: =IF(E1<基本数据!$J$19,E10-E10*基本数据!$J$23,0) -> 1063323.8 | G10: =IF(F1<基本数据!$J$19,F10-F10*基本数据!$J$23,0) -> 1047374 | H10: =IF(G1<基本数据!$J$19,G10-G10*基本数据!$J$23,0) -> 1031663.4 | I10: =IF(H1<基本数据!$J$19,H10-H10*基本数据!$J$23,0) -> 1016188.4 | J10: =IF(I1<基本数据!$J$19,I10-I10*基本数据!$J$23,0) -> 1000945.6 | K10: =IF(J1<基本数据!$J$19,J10-J10*基本数据!$J$23,0) -> 985931.4 | L10: =IF(K1<基本数据!$J$19,K10-K10*基本数据!$J$23,0) -> 971142.43 | ... AB10: =IF(AA1<基本数据!$J$19,AA10-AA10*基本数据!$J$23,0) -> 0
B11: 按需增容费 | D11: =IF((D1)<基本数据!$J$19,基本数据!$J$8*基本数据!$T$3*12,0) -> 0 | E11: =IF((E1)<基本数据!$J$19,基本数据!$J$8*基本数据!$T$3*12,0) -> 0 | F11: =IF((F1)<基本数据!$J$19,基本数据!$J$8*基本数据!$T$3*12,0) -> 0 | G11: =IF((G1)<基本数据!$J$19,基本数据!$J$8*基本数据!$T$3*12,0) -> 0 | H11: =IF((H1)<基本数据!$J$19,基本数据!$J$8*基本数据!$T$3*12,0) -> 0 | I11: =IF((I1)<基本数据!$J$19,基本数据!$J$8*基本数据!$T$3*12,0) -> 0 | J11: =IF((J1)<基本数据!$J$19,基本数据!$J$8*基本数据!$T$3*12,0) -> 0 | K11: =IF((K1)<基本数据!$J$19,基本数据!$J$8*基本数据!$T$3*12,0) -> 0 | ... AB11: =IF((AB1)<基本数据!$J$19,基本数据!$J$8*基本数据!$T$3*12,0) -> 0
B12: 充电服务费 | D12: =IF((D1-1)<基本数据!$O$12,基本数据!$O$6*基本数据!$O$7*365,0) -> 0 | E12: =IF((E1-1)<基本数据!$O$12,基本数据!$O$6*基本数据!$O$7*365,0) -> 0 | F12: =IF((F1-1)<基本数据!$O$12,基本数据!$O$6*基本数据!$O$7*365,0) -> 0 | G12: =IF((G1-1)<基本数据!$O$12,基本数据!$O$6*基本数据!$O$7*365,0) -> 0 | H12: =IF((H1-1)<基本数据!$O$12,基本数据!$O$6*基本数据!$O$7*365,0) -> 0 | I12: =IF((I1-1)<基本数据!$O$12,基本数据!$O$6*基本数据!$O$7*365,0) -> 0 | J12: =IF((J1-1)<基本数据!$O$12,基本数据!$O$6*基本数据!$O$7*365,0) -> 0 | K12: =IF((K1-1)<基本数据!$O$12,基本数据!$O$6*基本数据!$O$7*365,0) -> 0 | ... AB12: =IF((AB1-1)<基本数据!$O$12,基本数据!$O$6*基本数据!$O$7*365,0) -> 0
B13: 无功补偿费用 | D13: =IF((D1-1)<基本数据!$O$12,基本数据!$J$9*基本数据!$T$4*12,0) -> 0 | E13: =IF((E1-1)<基本数据!$O$12,基本数据!$J$9*基本数据!$T$4*12,0) -> 0 | F13: =IF((F1-1)<基本数据!$O$12,基本数据!$J$9*基本数据!$T$4*12,0) -> 0 | G13: =IF((G1-1)<基本数据!$O$12,基本数据!$J$9*基本数据!$T$4*12,0) -> 0 | H13: =IF((H1-1)<基本数据!$O$12,基本数据!$J$9*基本数据!$T$4*12,0) -> 0 | I13: =IF((I1-1)<基本数据!$O$12,基本数据!$J$9*基本数据!$T$4*12,0) -> 0 | J13: =IF((J1-1)<基本数据!$O$12,基本数据!$J$9*基本数据!$T$4*12,0) -> 0 | K13: =IF((K1-1)<基本数据!$O$12,基本数据!$J$9*基本数据!$T$4*12,0) -> 0 | ... AB13: =IF((AB1-1)<基本数据!$O$12,基本数据!$J$9*基本数据!$T$4*12,0) -> 0
B17: 收入合计 | D17: =D7+D8+D9+D10+D11+D12+D13+D14+D15+D16 -> 1095955.9 | E17: =E7+E8+E9+E10+E11+E12+E13+E14+E15+E16 -> 1079516.6 | F17: =F7+F8+F9+F10+F11+F12+F13+F14+F15+F16 -> 1063323.8 | G17: =G7+G8+G9+G10+G11+G12+G13+G14+G15+G16 -> 1047374 | H17: =H7+H8+H9+H10+H11+H12+H13+H14+H15+H16 -> 1031663.4 | I17: =I7+I8+I9+I10+I11+I12+I13+I14+I15+I16 -> 1016188.4 | J17: =J7+J8+J9+J10+J11+J12+J13+J14+J15+J16 -> 1000945.6 | K17: =K7+K8+K9+K10+K11+K12+K13+K14+K15+K16 -> 985931.4 | ... AB17: =AB7+AB8+AB9+AB10+AB11+AB12+AB13+AB14+AB15+AB16 -> 0
B19: 运营费用
B21: 设施维护费 | D21: =D17*基本数据!$E$32 -> 10959.559 | E21: =E17*基本数据!$E$32 -> 10795.166 | F21: =F17*基本数据!$E$32 -> 10633.238 | G21: =G17*基本数据!$E$32 -> 10473.74 | H21: =H17*基本数据!$E$32 -> 10316.634 | I21: =I17*基本数据!$E$32 -> 10161.884 | J21: =J17*基本数据!$E$32 -> 10009.456 | K21: =K17*基本数据!$E$32 -> 9859.314 | ... AB21: =AB17*基本数据!$E$32 -> 0
B23: 更换PCS及大修 | N23: =基本数据!$E$5*基本数据!$E$10*1000*10% -> 0 | Y23: =基本数据!$E$5*基本数据!$E$10*1000*10% -> 0
B25: 费用合计 | D25: =SUM(D20:D24) -> 10959.559 | E25: =SUM(E20:E24) -> 10795.166 | F25: =SUM(F20:F24) -> 10633.238 | G25: =SUM(G20:G24) -> 10473.74 | H25: =SUM(H20:H24) -> 10316.634 | I25: =SUM(I20:I24) -> 10161.884 | J25: =SUM(J20:J24) -> 10009.456 | K25: =SUM(K20:K24) -> 9859.314 | ... AB25: =SUM(AB20:AB24) -> 0
B27: 贷款 | C27: =基本数据!$E$31*(1-基本数据!$E$33) -> 0
B28: 等额本金 | D28: 0 | E28: 0 | F28: 0 | G28: 0 | H28: 0 | I28: 0 | J28: 0 | K28: 0 | L28: 0 | M28: 0 | N28: 0 | O28: 0 | P28: 0 | Q28: 0 | R28: 0 | S28: 0 | T28: 0 | U28: 0 | V28: 0 | W28: 0 | X28: 0 | Y28: 0 | Z28: 0 | AA28: 0 | AB28: 0
B29: -本金 | D29: =IF(D1>基本数据!$E$35,0,$C$27/基本数据!$E$35) -> 0 | E29: =IF(E1>基本数据!$E$35,0,$C$27/基本数据!$E$35) -> 0 | F29: =IF(F1>基本数据!$E$35,0,$C$27/基本数据!$E$35) -> 0 | G29: =IF(G1>基本数据!$E$35,0,$C$27/基本数据!$E$35) -> 0 | H29: =IF(H1>基本数据!$E$35,0,$C$27/基本数据!$E$35) -> 0 | I29: =IF(I1>基本数据!$E$35,0,$C$27/基本数据!$E$35) -> 0 | J29: =IF(J1>基本数据!$E$35,0,$C$27/基本数据!$E$35) -> 0 | K29: =IF(K1>基本数据!$E$35,0,$C$27/基本数据!$E$35) -> 0 | ... AB29: =IF(AB1>基本数据!$E$35,0,$C$27/基本数据!$E$35) -> 0
B30: -利息 | D30: =C27*基本数据!$E$34 -> 0 | E30: =(C27-D29)*基本数据!$E$34 -> 0 | F30: =(C27-D29-E29)*基本数据!$E$34 -> 0 | G30: =(C27-D29-E29-F29)*基本数据!$E$34 -> 0 | H30: =(C27-D29-E29-F29-G29)*基本数据!$E$34 -> 0 | J30: 0 | K30: 0 | L30: 0 | M30: 0 | N30: 0 | O30: 0 | P30: 0 | Q30: 0 | R30: 0 | S30: 0 | T30: 0 | U30: 0 | V30: 0 | W30: 0 | X30: 0 | Y30: 0 | Z30: 0 | AA30: 0 | AB30: 0
D31: 0 | E31: 0 | F31: 0 | G31: 0 | H31: 0 | I31: 0 | J31: 0 | K31: 0 | L31: 0 | M31: 0 | N31: 0 | O31: 0 | P31: 0 | Q31: 0 | R31: 0 | S31: 0 | T31: 0 | U31: 0 | V31: 0 | W31: 0 | X31: 0 | Y31: 0 | Z31: 0 | AA31: 0 | AB31: 0
B32: 等额本息 | D32: 0 | E32: 0 | F32: 0 | G32: 0 | H32: 0 | I32: 0 | J32: 0 | K32: 0 | L32: 0 | M32: 0 | N32: 0 | O32: 0 | P32: 0 | Q32: 0 | R32: 0 | S32: 0 | T32: 0 | U32: 0 | V32: 0 | W32: 0 | X32: 0 | Y32: 0 | Z32: 0 | AA32: 0 | AB32: 0
B33: -本金 | D33: 0 | E33: 0 | F33: 0 | G33: 0 | H33: 0 | I33: 0 | J33: 0 | K33: 0 | L33: 0 | M33: 0 | N33: 0 | O33: 0 | P33: 0 | Q33: 0 | R33: 0 | S33: 0 | T33: 0 | U33: 0 | V33: 0 | W33: 0 | X33: 0 | Y33: 0 | Z33: 0 | AA33: 0 | AB33: 0
B34: -利息 | D34: 0 | E34: 0 | F34: 0 | G34: 0 | H34: 0 | I34: 0 | J34: 0 | K34: 0 | L34: 0 | M34: 0 | N34: 0 | O34: 0 | P34: 0 | Q34: 0 | R34: 0 | S34: 0 | T34: 0 | U34: 0 | V34: 0 | W34: 0 | X34: 0 | Y34: 0 | Z34: 0 | AA34: 0 | AB34: 0
D35: 0 | E35: 0 | F35: 0 | G35: 0 | H35: 0 | I35: 0 | J35: 0 | K35: 0 | L35: 0 | M35: 0 | N35: 0 | O35: 0 | P35: 0 | Q35: 0 | R35: 0 | S35: 0 | T35: 0 | U35: 0 | V35: 0 | W35: 0 | X35: 0 | Y35: 0 | Z35: 0 | AA35: 0 | AB35: 0
B36: 贷款合计 | D36: =SUM(D28:D35) -> 0 | E36: =SUM(E28:E35) -> 0 | F36: =SUM(F28:F35) -> 0 | G36: =SUM(G28:G35) -> 0 | H36: =SUM(H28:H35) -> 0 | I36: =SUM(I28:I35) -> 0 | J36: =SUM(J28:J35) -> 0 | K36: =SUM(K28:K35) -> 0 | ... AB36: =SUM(AB28:AB35) -> 0
B38: 税费
B39: 累计收入 | D39: =SUM(D17) -> 1095955.9 | E39: =SUM(D17:E17) -> 2175472.5 | F39: =SUM(D17:F17) -> 3238796.3 | G39: =F39+G17 -> 4286170.3 | H39: =G39+H17 -> 5317833.7 | I39: =H39+I17 -> 6334022.1 | J39: =I39+J17 -> 7334967.7 | K39: =J39+K17 -> 8320899.1 | L39: =K39+L17 -> 9292041.5 | M39: =L39+M17 -> 9292041.5 | N39: =M39+N17 -> 9292041.5 | ... AB39: =AA39+AB17 -> 9292041.5
B40: 增值税 | D40: =IF(D39<(基本数据!$E$5*1000*基本数据!$E$10+基本数据!$J$5*1000*基本数据!$J$16+基本数据!$O$9),0,(D17-D12)/1.16*16%+D12/1.06*6%) -> 0 | E40: =IF(E39<(基本数据!$E$5*1000*基本数据!$E$10+基本数据!$J$5*1000*基本数据!$J$16+基本数据!$O$9),0,(E17-E12)/1.16*16%+E12/1.06*6%) -> 0 | F40: =IF(F39<(基本数据!$E$5*1000*基本数据!$E$10+基本数据!$J$5*1000*基本数据!$J$16+基本数据!$O$9),0,(F17-F12)/1.16*16%+F12/1.06*6%) -> 0 | G40: =IF(G39<(基本数据!$E$5*1000*基本数据!$E$10+基本数据!$J$5*1000*基本数据!$J$16+基本数据!$O$9),0,(G17-G12)/1.16*16%+G12/1.06*6%) -> 0 | H40: =IF(H39<(基本数据!$E$5*1000*基本数据!$E$10+基本数据!$J$5*1000*基本数据!$J$16+基本数据!$O$9),0,(H17-H12)/1.16*16%+H12/1.06*6%) -> 0 | I40: =IF(I39<(基本数据!$E$5*1000*基本数据!$E$10+基本数据!$J$5*1000*基本数据!$J$16+基本数据!$O$9),0,(I17-I12)/1.16*16%+I12/1.06*6%) -> 0 | J40: =IF(J39<(基本数据!$E$5*1000*基本数据!$E$10+基本数据!$J$5*1000*基本数据!$J$16+基本数据!$O$9),0,(J17-J12)/1.16*16%+J12/1.06*6%) -> 0 | K40: =IF(K39<(基本数据!$E$5*1000*基本数据!$E$10+基本数据!$J$5*1000*基本数据!$J$16+基本数据!$O$9),0,(K17-K12)/1.16*16%+K12/1.06*6%) -> 135990.54 | ... AB40: =IF(AB39<(基本数据!$E$5*1000*基本数据!$E$10+基本数据!$J$5*1000*基本数据!$J$16+基本数据!$O$9),0,(AB17-AB12)/1.16*16%+AB12/1.06*6%) -> 0
B41: 增值税附加 | D41: =D40*10% -> 0 | E41: =E40*10% -> 0 | F41: =F40*10% -> 0 | G41: =G40*10% -> 0 | H41: =H40*10% -> 0 | I41: =I40*10% -> 0 | J41: =J40*10% -> 0 | K41: =K40*10% -> 13599.054 | ... AB41: =AB40*10% -> 0
B43: 折旧 | D43: =IF(D8>0,基本数据!$E$5*1000*基本数据!$E$10/25/1.16,0)+IF(D10>0,基本数据!$J$5*1000*基本数据!$J$16/基本数据!$J$19/1.16,0)+IF(D12>0,基本数据!$O$9/基本数据!$O$12/1.16,0) -> 781393.68 | E43: =IF(E8>0,基本数据!$E$5*1000*基本数据!$E$10/25/1.16,0)+IF(E10>0,基本数据!$J$5*1000*基本数据!$J$16/基本数据!$J$19/1.16,0)+IF(E12>0,基本数据!$O$9/基本数据!$O$12/1.16,0) -> 781393.68 | F43: =IF(F8>0,基本数据!$E$5*1000*基本数据!$E$10/25/1.16,0)+IF(F10>0,基本数据!$J$5*1000*基本数据!$J$16/基本数据!$J$19/1.16,0)+IF(F12>0,基本数据!$O$9/基本数据!$O$12/1.16,0) -> 781393.68 | G43: =IF(G8>0,基本数据!$E$5*1000*基本数据!$E$10/25/1.16,0)+IF(G10>0,基本数据!$J$5*1000*基本数据!$J$16/基本数据!$J$19/1.16,0)+IF(G12>0,基本数据!$O$9/基本数据!$O$12/1.16,0) -> 781393.68 | H43: =IF(H8>0,基本数据!$E$5*1000*基本数据!$E$10/25/1.16,0)+IF(H10>0,基本数据!$J$5*1000*基本数据!$J$16/基本数据!$J$19/1.16,0)+IF(H12>0,基本数据!$O$9/基本数据!$O$12/1.16,0) -> 781393.68 | I43: =IF(I8>0,基本数据!$E$5*1000*基本数据!$E$10/25/1.16,0)+IF(I10>0,基本数据!$J$5*1000*基本数据!$J$16/基本数据!$J$19/1.16,0)+IF(I12>0,基本数据!$O$9/基本数据!$O$12/1.16,0) -> 781393.68 | J43: =IF(J8>0,基本数据!$E$5*1000*基本数据!$E$10/25/1.16,0)+IF(J10>0,基本数据!$J$5*1000*基本数据!$J$16/基本数据!$J$19/1.16,0)+IF(J12>0,基本数据!$O$9/基本数据!$O$12/1.16,0) -> 781393.68 | K43: =IF(K8>0,基本数据!$E$5*1000*基本数据!$E$10/25/1.16,0)+IF(K10>0,基本数据!$J$5*1000*基本数据!$J$16/基本数据!$J$19/1.16,0)+IF(K12>0,基本数据!$O$9/基本数据!$O$12/1.16,0) -> 781393.68 | ... AB43: =IF(AB8>0,基本数据!$E$5*1000*基本数据!$E$10/25/1.16,0)+IF(AB10>0,基本数据!$J$5*1000*基本数据!$J$16/基本数据!$J$19/1.16,0)+IF(AB12>0,基本数据!$O$9/基本数据!$O$12/1.16,0) -> 0
B44: 所得税 | D44: =IF(((D17-D12)/1.13+D12/1.06-D25/1.13-D30-D34-D43)*0.25>0,((D17-D12)/1.13+D12/1.06-D25/1.13-D30-D34-D43)*0.25,0) -> 44695.023 | E44: =IF(((E17-E12)/1.13+E12/1.06-E25/1.13-E30-E34-E43)*0.25>0,((E17-E12)/1.13+E12/1.06-E25/1.13-E30-E34-E43)*0.25,0) -> 41094.371 | F44: =IF(((F17-F12)/1.13+F12/1.06-F25/1.13-F30-F34-F43)*0.25>0,((F17-F12)/1.13+F12/1.06-F25/1.13-F30-F34-F43)*0.25,0) -> 37547.73 | G44: =IF(((G17-G12)/1.13+G12/1.06-G25/1.13-G30-G34-G43)*0.25>0,((G17-G12)/1.13+G12/1.06-G25/1.13-G30-G34-G43)*0.25,0) -> 34054.287 | H44: =IF(((H17-H12)/1.13+H12/1.06-H25/1.13-H30-H34-H43)*0.25>0,((H17-H12)/1.13+H12/1.06-H25/1.13-H30-H34-H43)*0.25,0) -> 30613.247 | I44: =IF(((I17-I12)/1.13+I12/1.06-I25/1.13-I30-I34-I43)*0.25>0,((I17-I12)/1.13+I12/1.06-I25/1.13-I30-I34-I43)*0.25,0) -> 27223.822 | J44: =IF(((J17-J12)/1.13+J12/1.06-J25/1.13-J30-J34-J43)*0.25>0,((J17-J12)/1.13+J12/1.06-J25/1.13-J30-J34-J43)*0.25,0) -> 23885.238 | K44: =IF(((K17-K12)/1.13+K12/1.06-K25/1.13-K30-K34-K43)*0.25>0,((K17-K12)/1.13+K12/1.06-K25/1.13-K30-K34-K43)*0.25,0) -> 20596.733 | ... AB44: =IF(((AB17-AB12)/1.13+AB12/1.06-AB25/1.13-AB30-AB34-AB43)*0.25>0,((AB17-AB12)/1.13+AB12/1.06-AB25/1.13-AB30-AB34-AB43)*0.25,0) -> 0
B46: 税费汇总 | D46: =SUM(D40:D41,D44) -> 44695.023 | E46: =SUM(E40:E41,E44) -> 41094.371 | F46: =SUM(F40:F41,F44) -> 37547.73 | G46: =SUM(G40:G41,G44) -> 34054.287 | H46: =SUM(H40:H41,H44) -> 30613.247 | I46: =SUM(I40:I41,I44) -> 27223.822 | J46: =SUM(J40:J41,J44) -> 23885.238 | K46: =SUM(K40:K41,K44) -> 170186.33 | ... AB46: =SUM(AB40:AB41,AB44) -> 0
B48: 累计现金净流入 | C48: =-基本数据!$E$31*基本数据!E33 -> -5215000 | D48: =D17-D25-D36-D46 -> 1040301.3 | E48: =E17-E25-E36-E46 -> 1027627 | F48: =F17-F25-F36-F46 -> 1015142.9 | G48: =G17-G25-G36-G46 -> 1002845.9 | H48: =H17-H25-H36-H46 -> 990733.48 | I48: =I17-I25-I36-I46 -> 978802.71 | J48: =J17-J25-J36-J46 -> 967050.89 | K48: =K17-K25-K36-K46 -> 805885.77 | ... AB48: =AB17-AB25-AB36-AB46 -> 0
B49: 现金流 | C49: =C48 -> -5215000 | D49: =C49+D48 -> -4174698.7 | E49: =D49+E48 -> -3147071.6 | F49: =E49+F48 -> -2131928.8 | G49: =F49+G48 -> -1129082.8 | H49: =G49+H48 -> -138349.32 | I49: =H49+I48 -> 840453.39 | J49: =I49+J48 -> 1807504.3 | K49: =J49+K48 -> 2613390 | ... AB49: =AA49+AB48 -> 3410117.8
D50: =IF(D56=1,D49,0) -> -4174698.7 | E50: =IF(E56=1,E49,0) -> -3147071.6 | F50: =IF(F56=1,F49,0) -> -2131928.8 | G50: =IF(G56=1,G49,0) -> -1129082.8 | H50: =IF(H56=1,H49,0) -> -138349.32 | I50: =IF(I56=1,I49,0) -> 0 | J50: =IF(J56=1,J49,0) -> 0 | K50: =IF(K56=1,K49,0) -> 0 | ... AB50: =IF(AB56=1,AB49,0) -> 0
B51: 税前收入 | C51: =C48 -> -5215000 | D51: =D48+D46 -> 1084996.4 | E51: =E48+E46 -> 1068721.4 | F51: =F48+F46 -> 1052690.6 | G51: =G48+G46 -> 1036900.2 | H51: =H48+H46 -> 1021346.7 | I51: =I48+I46 -> 1006026.5 | J51: =J48+J46 -> 990936.13 | K51: =K48+K46 -> 976072.09 | ... AB51: =AB48+AB46 -> 0
C52: =C49 -> -5215000 | D52: =C52+D51 -> -4130003.6 | E52: =D52+E51 -> -3061282.2 | F52: =E52+F51 -> -2008591.6 | G52: =F52+G51 -> -971691.39 | H52: =G52+H51 -> 49655.337 | I52: =H52+I51 -> 1055681.9 | J52: =I52+J51 -> 2046618 | K52: =J52+K51 -> 3022690.1 | ... AB52: =AA52+AB51 -> 3984121.1
D53: =IF(D54=1,D52,0) -> -4130003.6 | E53: =IF(E54=1,E52,0) -> -3061282.2 | F53: =IF(F54=1,F52,0) -> -2008591.6 | G53: =IF(G54=1,G52,0) -> -971691.39 | H53: =IF(H54=1,H52,0) -> 0 | I53: =IF(I54=1,I52,0) -> 0 | J53: =IF(J54=1,J52,0) -> 0 | K53: =IF(K54=1,K52,0) -> 0 | ... AB53: =IF(AB54=1,AB52,0) -> 0
...

Sheet 储能敏感性分析
A1: 一天充放一次
A3: 序号 | B3: 项目 | C3: 财务内部收益率（%）
C4: 全部投资（所得税前） | D4: 全部投资（所得税后） | E4: 投资 | F4: 考虑30%残值
A5: 1 | B5: 基本方案 | C5: 0.0834 | D5: 0.056 | E5: 1.30375
A6: 2 | B6: 投资变化
B7: 0.2 | C7: 0.0559 | D7: 0.0351 | E7: =$E$5+$E$5*B7 -> 1.5645 | F7: =E7-E7*0.3 -> 1.09515
B8: 0.15 | C8: 0.0621 | D8: 0.0402 | E8: =$E$5+$E$5*B8 -> 1.4993125 | F8: =E8-E8*0.3 -> 1.0495188
B9: 0.1 | C9: 0.0689 | D9: 0.0439 | E9: =$E$5+$E$5*B9 -> 1.434125 | F9: =E9-E9*0.3 -> 1.0038875
B10: 0.05 | C10: 0.0757 | D10: 0.0497 | E10: =$E$5+$E$5*B10 -> 1.3689375 | F10: =E10-E10*0.3 -> 0.95825625
B11: -0.05 | C11: 0.0916 | D11: 0.0609 | E11: =$E$5+$E$5*B11 -> 1.2385625 | F11: =E11-E11*0.3 -> 0.86699375
B12: -0.1 | C12: 0.1006 | D12: 0.0683 | E12: =$E$5+$E$5*B12 -> 1.173375 | F12: =E12-E12*0.3 -> 0.8213625
B13: -0.15 | C13: 0.1103 | D13: 0.0742 | E13: =$E$5+$E$5*B13 -> 1.1081875 | F13: =E13-E13*0.3 -> 0.77573125
B14: -0.2 | C14: 0.1211 | D14: 0.083 | E14: =$E$5+$E$5*B14 -> 1.043 | F14: =E14-E14*0.3 -> 0.7301
A15: 3 | E15: 0.6098
B16: 电价变化 | E16: 峰谷
B17: 0.2 | C17: 0.12470524 | D17: 0.08597732 | E17: =$E$15+$E$15*B17 -> 0.73176
B18: 0.15 | C18: 0.11746829 | D18: 0.08003781 | E18: =$E$15+$E$15*B18 -> 0.70127
B19: 0.1 | C19: 0.11012007 | D19: 0.074016401 | E19: =$E$15+$E$15*B19 -> 0.67078
B20: 0.05 | C20: 0.10076189 | D20: 0.068461571 | E20: =$E$15+$E$15*B20 -> 0.64029
B21: -0.05 | C21: 0.085330459 | D21: 0.055773926 | E21: =$E$15+$E$15*B21 -> 0.57931
B22: -0.1 | C22: 0.077370919 | D22: 0.051072151 | E22: =$E$15+$E$15*B22 -> 0.54882
B23: -0.15 | C23: 0.067156215 | D23: 0.042682151 | E23: =$E$15+$E$15*B23 -> 0.51833
B24: -0.2 | C24: 0.058744957 | D24: 0.037433215 | E24: =$E$15+$E$15*B24 -> 0.48784
A25: 注：基本方案，投资1.30375元/Wh，电价差0.6098元/kWh
A28: 一天充放两次
A30: 序号 | B30: 项目 | C30: 财务内部收益率（%）
C31: 全部投资（所得税前） | D31: 全部投资（所得税后） | E31: 投资 | F31: 考虑30%残值
A32: 1 | B32: 基本方案 | C32: 0.10645948 | D32: 0.063067632 | E32: 1.30375
A33: 2 | B33: 投资变化
B34: 0.2 | C34: 0.058207009 | D34: 0.030229391 | E34: =$E$5+$E$5*B34 -> 1.5645 | F34: =E34-E34*0.3 -> 1.09515
B35: 0.15 | C35: 0.069042755 | D35: 0.038913869 | E35: =$E$5+$E$5*B35 -> 1.4993125 | F35: =E35-E35*0.3 -> 1.0495188
B36: 0.1 | C36: 0.080629988 | D36: 0.04823789 | E36: =$E$5+$E$5*B36 -> 1.434125 | F36: =E36-E36*0.3 -> 1.0038875
B37: 0.05 | C37: 0.093064333 | D37: 0.058282411 | E37: =$E$5+$E$5*B37 -> 1.3689375 | F37: =E37-E37*0.3 -> 0.95825625
B38: -0.05 | C38: 0.12095183 | D38: 0.074727109 | E38: =$E$5+$E$5*B38 -> 1.2385625 | F38: =E38-E38*0.3 -> 0.86699375
B39: -0.1 | C39: 0.1367066 | D39: 0.087450751 | E39: =$E$5+$E$5*B39 -> 1.173375 | F39: =E39-E39*0.3 -> 0.8213625
B40: -0.15 | C40: 0.15392618 | D40: 0.10140788 | E40: =$E$5+$E$5*B40 -> 1.1081875 | F40: =E40-E40*0.3 -> 0.77573125
B41: -0.2 | C41: 0.1728615 | D41: 0.10924792 | E41: =$E$5+$E$5*B41 -> 1.043 | F41: =E41-E41*0.3 -> 0.7301
A42: 3 | E42: 0.6098 | F42: 0.3094
B43: 电价变化 | E43: 峰谷 | F43: 峰平
B44: 0.2 | C44: 0.16081053 | D44: 0.10700102 | E44: =$E$15+$E$15*B44 -> 0.73176 | F44: =$F$42+$F$42*B44 -> 0.37128
...
