Workbook

Sheet 封面
A1: 苏南运河干（支）线数字化转型升级项目施工项目（SZH-SNSG1标段）
A4: 工程量清单
A6: 招 标 人： | B6: 江苏省交通运输厅港航事业发展中心
A7: 投 标 人： | D7: （电子签章）
A8: 编制时间：

Sheet 说明
A1: 工程量清单说明
A2: 项目名称：苏南运河干（支）线数字化转型升级项目施工项目（SZH-SNSG1标段）
A3: 1.本工程量清单应与招标文件中的投标人须知、通用合同条款、专用合同条款、工程量清单计量规则、技术标准和要求及图纸等一起阅读和理解。
A4: 2.工程量清单中所列工程量的变动，丝毫不会降低或影响合同条款的效力，也不免除承包人按规定的标准进行施工和修复缺陷的责任。
A5: 3.图纸中所列的工程数量表及数量汇总表仅是提供资料，不是工程量清单的外延。当图纸与工程量清单所列数量不一致时，以工程量清单所列数量作为报价的依据。
A6: 4.承包人负责与供电部门协调沟通，负责点位开户挂电表，含供电线路、相关接入设备、设备安装调试、架空或埋地线路等工作量，至交工验收后5年内的合同范围内所有设备系统运行等所发生的电费由承包人承担，上述费用均含在相关细目报价中，不单独计量与支付。
A7: 5.承包人负责网络的接入工作，含通信光缆、相关接入设备、设备安装调试、架空或埋地线路等工作量，至交工验收后5年内的网络租赁和使用费应由承包人承担，具体数量及要求详见设计文件，上述费用均含在相关细目报价中，不单独计量与支付。
A8: 6.杆件（立杆）费用中包含点位所需设备与杆件运输、杆件施工、辅材配件采购、线缆线路敷设、设备及配件安装、绿化破坏补偿恢复等全部费用。
A9: 7.对于工程量清单中所有为完成相关设备或系统安装和调试所需的、但未在工程量清单中列出的辅材(包括设备安装附件、跳纤、尾纤、插头、接头等)，费用包含在清单单价或总价中。
A10: 8.工程量清单中各项金额均以人民币（元）结算。

Sheet 汇总表
A1: 汇总表
A2: =说明!A2 -> 项目名称：苏南运河干（支）线数字化转型升级项目施工项目（SZH-SNSG1标段）
A3: 序号 | B3: 项目名称 | C3: 金额（元）
A4: 一 | B4: 应用软件建设费 | C4: =SUM(工程量清单!G8:G120) -> 0
A5: 二 | B5: 数据工程费 | C5: =SUM(工程量清单!G126:G149) -> 0
A6: 三 | B6: 设备及购置安装费 | C6: =SUM(工程量清单!G155:G402) -> 0
A7: 四 | B7: 工程其他费用 | C7: =SUM(工程量清单!G404:G405) -> 0
A8: 五 | B8: 清单小计 | C8: =ROUND(SUM(C4:C7),0) -> 0
A9: 六 | B9: 暂列金（3%） | C9: =ROUND(C8*3%,0) -> 0
A10: 七 | B10: 安全生产费（1.5%） | C10: =ROUND(21230000*1.5%,0) -> 318450
A11: 八 | B11: 工伤保险费（3‰） | C11: =ROUND(21230000*0.3%,0) -> 63690
A12: 总计 | C12: =SUM(C8:C11) -> 382140
B14: 投标人： | C14: （电子签章）
B16: 法定代表人或其授权代理人： | C16: （电子签章）
B18: 日期：

Sheet 工程量清单
A1: 工程量清单
A2: =说明!A2 -> 项目名称：苏南运河干（支）线数字化转型升级项目施工项目（SZH-SNSG1标段）
A3: 序号 | B3: 项目名称 | C3: 主要建设内容 | D3: 单位 | E3: 数量 | F3: 单价 （元） | G3: 合价 （元） | H3: 备注
A4: 一 | B4: 应用软件建设费
A5: 1.1 | B5: 智慧船闸
A6: 1.1.1 | B6: 航闸数字孪生系统 | H6: 杨家湾船闸、下坝二号船闸
A7: 1.1.1.1 | B7: 数字孪生引擎
A8: -1 | B8: WebGL引擎及二次开发 | C8: 详见施工图设计方案 | D8: 项 | E8: 1 | G8: =ROUND(E8*F8,2) -> 0
A9: -2 | B9: 高渲染引擎及二次开发 | C9: 详见施工图设计方案 | D9: 项 | E9: 1 | G9: =ROUND(E9*F9,2) -> 0
A10: 1.1.1.2 | B10: 数字孪生门户
A11: -1 | B11: 用户登录 | C11: 详见施工图设计方案 | D11: 项 | E11: 1 | G11: =ROUND(E11*F11,2) -> 0
A12: -2 | B12: 门户首页 | C12: 详见施工图设计方案 | D12: 项 | E12: 1 | G12: =ROUND(E12*F12,2) -> 0
A13: 1.1.1.3 | B13: 船闸三维可视化
A14: 1.1.1.3.1 | B14: 多图层智能叠加
A15: -1 | B15: 三维电子地图图层 | C15: 详见施工图设计方案 | D15: 项 | E15: 1 | G15: =ROUND(E15*F15,2) -> 0
A16: -2 | B16: 电子航道图图层 | C16: 详见施工图设计方案 | D16: 项 | E16: 1 | G16: =ROUND(E16*F16,2) -> 0
A17: -3 | B17: 三维/航道图叠加图层 | C17: 详见施工图设计方案 | D17: 项 | E17: 1 | G17: =ROUND(E17*F17,2) -> 0
A18: 1.1.1.3.2 | B18: 多视角智能切换 | C18: 详见施工图设计方案 | D18: 项 | E18: 1 | G18: =ROUND(E18*F18,2) -> 0
A19: 1.1.1.3.3 | B19: 基础设施查询定位
A20: -1 | B20: 树状目录查询 | C20: 详见施工图设计方案 | D20: 项 | E20: 1 | G20: =ROUND(E20*F20,2) -> 0
A21: -2 | B21: 属性检索查询 | C21: 详见施工图设计方案 | D21: 项 | E21: 1 | G21: =ROUND(E21*F21,2) -> 0
A22: 1.1.1.3.4 | B22: 船闸设施可视
A23: -1 | B23: 闸室可视 | C23: 详见施工图设计方案 | D23: 项 | E23: 1 | G23: =ROUND(E23*F23,2) -> 0
A24: -2 | B24: 闸室水下可视 | C24: 详见施工图设计方案 | D24: 项 | E24: 1 | G24: =ROUND(E24*F24,2) -> 0
A25: 1.1.1.3.5 | B25: 关联航道设施可视
A26: -1 | B26: 航道 | C26: 详见施工图设计方案 | D26: 项 | E26: 1 | G26: =ROUND(E26*F26,2) -> 0
A27: -2 | B27: 护岸 | C27: 详见施工图设计方案 | D27: 项 | E27: 1 | G27: =ROUND(E27*F27,2) -> 0
A28: -3 | B28: 水下地形 | C28: 详见施工图设计方案 | D28: 项 | E28: 1 | G28: =ROUND(E28*F28,2) -> 0
A29: -4 | B29: 桥梁 | C29: 详见施工图设计方案 | D29: 项 | E29: 1 | G29: =ROUND(E29*F29,2) -> 0
A30: -5 | B30: 感知设施 | C30: 详见施工图设计方案 | D30: 项 | E30: 1 | G30: =ROUND(E30*F30,2) -> 0
A31: -6 | B31: 停泊区 | C31: 详见施工图设计方案 | D31: 项 | E31: 1 | G31: =ROUND(E31*F31,2) -> 0
A32: 1.1.1.3.6 | B32: 船舶可视
A33: -1 | B33: 类型匹配 | C33: 详见施工图设计方案 | D33: 项 | E33: 1 | G33: =ROUND(E33*F33,2) -> 0
A34: -2 | B34: 尺寸匹配 | C34: 详见施工图设计方案 | D34: 项 | E34: 1 | G34: =ROUND(E34*F34,2) -> 0
A35: 1.1.1.4 | B35: 船闸运营智能监测
A36: 1.1.1.4.1 | B36: 视频汇聚联动
A37: -1 | B37: 视频自动匹配、联动、切换 | C37: 详见施工图设计方案 | D37: 项 | E37: 1 | G37: =ROUND(E37*F37,2) -> 0
A38: -2 | B38: 无人机视频对接 | C38: 详见施工图设计方案 | D38: 项 | E38: 1 | G38: =ROUND(E38*F38,2) -> 0
A39: -3 | B39: 闸室全景视频展示、标注 | C39: 详见施工图设计方案 | D39: 项 | E39: 1 | G39: =ROUND(E39*F39,2) -> 0
A40: 1.1.1.4.2 | B40: 船闸智能监测
...
