Workbook

Sheet 封面
A1: 苏南运河干（支）线数字化转型升级项目施工项目（SZH-SNSG5标段）
A4: 工程量清单
A6: 招 标 人： | B6: 江苏省交通运输厅港航事业发展中心
A7: 投 标 人： | D7: （电子签章）
A8: 编制时间：

Sheet 说明
A1: 工程量清单说明
A2: 项目名称：苏南运河干（支）线数字化转型升级项目施工项目（SZH-SNSG5标段）
A3: 1.本工程量清单应与招标文件中的投标人须知、通用合同条款、专用合同条款、工程量清单计量规则、技术规范及图纸等一起阅读和理解。
A4: 2.工程量清单中所列工程量的变动，丝毫不会降低或影响合同条款的效力，也不免除承包人按规定的标准进行施工和修复缺陷的责任。
A5: 3.图纸中所列的工程数量表及数量汇总表仅是提供资料，不是工程量清单的外延。当图纸与工程量清单所列数量不一致时，以工程量清单所列数量作为报价的依据。
A6: 4.承包人负责与供电部门协调沟通，负责点位开户挂电表，含供电线路、相关接入设备、设备安装调试、架空或埋地线路等工作量，至交工验收后5年内的合同范围内所有设备系统运行等所发生的电费由承包人承担，上述费用均含在相关细目报价中，不单独计量与支付。
A7: 5.承包人负责网络的接入工作，含通信光缆、相关接入设备、设备安装调试、架空或埋地线路等工作量，至交工验收后5年内的网络租赁和使用费应由承包人承担，具体数量及要求详见设计文件，上述费用均含在相关细目报价中，不单独计量与支付。
A8: 6.杆件（立杆）费用中包含点位所需设备与杆件运输、杆件施工、辅材配件采购、线缆线路敷设、设备及配件安装、绿化破坏补偿恢复等全部费用。
A9: 7.对于工程量清单中所有为完成相关设备或系统安装和调试所需的、但未在工程量清单中列出的辅材(包括设备安装附件、跳纤、尾纤、插头、接头等)，费用包含在清单单价或总价中。
A10: 8.工程量清单中各项金额均以人民币（元）结算。

Sheet 汇总
A1: 汇总表
A2: =说明!A2 -> 项目名称：苏南运河干（支）线数字化转型升级项目施工项目（SZH-SNSG5标段）
A3: 序号 | B3: 项目名称 | C3: 金额（元）
A4: 一 | B4: 数据工程费 | C4: =SUM(工程量清单!G7:G10) -> 0
A5: 二 | B5: 设备购置及安装调试费 | C5: =SUM(工程量清单!G15:G308) -> 0
A6: 三 | B6: 工程其他费用 | C6: =SUM(工程量清单!G310:G311) -> 0
A7: 四 | B7: 清单小计 | C7: =ROUND(SUM(C4:C6),0) -> 0
A8: 五 | B8: 暂列金（3%） | C8: =ROUND(C7*3%,0) -> 0
A9: 六 | B9: 安全生产费（1.5%） | C9: =ROUND(19190000*1.5%,0) -> 287850
A10: 七 | B10: 工伤保险费（3‰） | C10: =ROUND(19190000*0.3%,0) -> 57570
A11: 总计 | C11: =SUM(C7:C10) -> 345420
B13: 投标人： | C13: （电子签章）
B15: 法定代表人或其授权代理人： | C15: （电子签章）
B17: 日期：

Sheet 工程量清单
A1: 工程量清单
A2: =说明!A2 -> 项目名称：苏南运河干（支）线数字化转型升级项目施工项目（SZH-SNSG5标段）
A3: 序号 | B3: 项目名称 | C3: 主要建设内容 | D3: 单位 | E3: 数量 | F3: 单价 （元） | G3: 小计 （元） | H3: 备注
A4: 一 | B4: 数据工程费
A5: 1.1 | B5: 智慧船闸
A6: 1.1.1 | B6: 航道数字孪生数据
A7: 1.1.1.1 | B7: 辖区内苏南运河航道采集建模（含护岸、桥梁、航标等粗模） | C7: 航道采集建模宽度0.4km | D7: 公里 | E7: 82 | G7: =ROUND(E7*F7,2) -> 0
A8: 1.1.2 | B8: 与省市系统对接 | D8: 项 | E8: 1 | G8: =ROUND(E8*F8,2) -> 0
A9: 1.2 | B9: 智慧水上服务区
A10: 1.2.1 | B10: 与省市系统对接 | D10: 项 | E10: 1 | G10: =ROUND(E10*F10,2) -> 0
A11: 二 | B11: 设备购置费
A12: 2.1 | B12: 智慧船闸
A13: 2.1.1 | B13: 张家港二号闸
A14: 2.1.1.1 | B14: 远调站船舶吃水、超高检测设备
A15: （1） | B15: 检测相机 | C15: 具体技术要求： 1、不低于400万像素； 2、宽动态：不低于120 dB； 3、最低照度：彩色模式：≤0.0005lx，黑白模式：≤0.0001lx； 4、传感器类型：不小于1/1.8英寸CMOS； 5、焦距：不小于2.8~12 mm，拍摄距离满足本项目检测距离需求； 6、补光：混光（红外+暖白），不低于4颗灯珠，补光距离不小于50m，具备补光自适应功能； 7、视频压缩标准：H.265/H.264/MJPEG； 8、网络：具备RJ45 10 M/100 M/1000 M自适应以太网口、RS-485接口； 9、报警：具备掉线、遮挡报警等功能，提供SDK包二次开发使用； 10、报警信号联动：不少于3路输入、2路输出； 11、具有独立的IP地址，可以直接接入以太网络，并可以通过客户端自动搜索IP地址； 12、供电方式：支持DC12V/PoE供电，具备防反接保护； 13、功能：内置GPU，具备防抖、降噪、加热、除湿等功能，具备防雷、防浪涌保护； 14、工作温湿度：温度不低于-30 °C~60 °C，湿度不低于5%~95%@40℃，无凝结； 15、防护：不低于IP66； 16、含接地、安装支架等配套设备。 17、含五年原厂质保 | D15: 台 | E15: 2 | G15: =ROUND(E15*F15,2) -> 0
A16: （2） | B16: 抓拍相机 | C16: 具体技术要求： 1、不低于800万像素； 2、采用不小于1英寸CMOS； 3、视频采用H.265、H.264或MJPEG编码； 4、图像控制：曝光速度、AGC控制、白平衡方式控制等； 5、压缩输出码率：不低于32 Kbps~16 Mbps； 6、镜头规格：25mm，拍摄距离满足本项目抓拍距离需求； 7、快门速度是 50us到9000us； 8、光圈类型：自动光圈或手动光圈（支持远程调节）； 9、触发输出：不少于4路F+/F-输出接口，作为补光灯同步输出控制； 10、触发输入：不少于1路触发/报警输入； 11、补光：暖白光，不低于3颗灯珠，补光距离不小于40米；具备补光自适应功能； 12、功能：内置GPU，具备防抖、降噪、加热、除湿等功能，具备防雷、防浪涌保护； 13、通讯接口：具备RJ45 10 M/100 M/1000 M自适应以太网口、RS-485接口； 14、报警：具备掉线、遮挡报警等功能，提供SDK包二次开发使用； 15、具有独立的IP地址，可以直接接入以太网络，并可以通过客户端自动搜索IP地址； 16、工作温湿度：温度不低于-30 °C~70 °C，湿度不低于5%~95%@40℃，无凝结； 17、防护：不低于IP66； 18、含接地、安装支架等配套设备； 19、五年原厂质保 | D16: 台 | E16: 2 | G16: =ROUND(E16*F16,2) -> 0
A17: （3） | B17: 长距激光雷达 | C17: 具体技术要求： 1、单帧线束：不低于128线； 2、激光波长：不低于905nm； 3、探测范围：不弱于1.5~400m； 4、探测距离：最远探测距离400m ，在10%反射率条件下≥250m； 5、视场角：不低于(H*V) 120°X 18°； 6、角分辨率：不高于(H*V)0.16°* 0.17°； 7、防水及防尘等级：IP67； 8、测距精度：土3cm(1σ)； 9、帧率：5~20FPS，可调节； 10、工作温度： -40℃~85℃； 11、储存温度：-40℃~105℃； 12、人眼安全等级：Class1(IEC-60825)； 13、额定电压：12/24V DC； 14、额定功率：<20w； 15、数据传输接口：1000Base-T1以太网； 16、点云扫描点频：不低于80万点/秒； 17、时间同步：具备网络时间同步功能； 18、五年原厂质保 | D17: 台 | E17: 2 | G17: =ROUND(E17*F17,2) -> 0
A18: （4） | B18: 补光灯 | C18: 具体技术要求： 1、灯珠：不少于24颗LED光源； 2、补光方式：支持LED频闪、LED爆闪、白光气体爆闪及红外气体爆闪四种补光方式； 3、光源波长：混合光源（红外+暖白光）； 4、发光角度：满足相机实际使用需求； 5、最佳投射距离：不低于20米，满足实际抓拍补光要求； 6、亮度调节： 自动控制； 7、工作环境温度：不低于-30℃ - 60℃； 8、工作环境湿度：湿度小于95%，无凝结； 9、外壳材质：金属铝； 10、防护等级：不低于IP66； 11、安装方式：万向节等安装方式，含安装支架等辅材。 | D18: 台 | E18: 2 | G18: =ROUND(E18*F18,2) -> 0
A19: （5） | B19: AIS接收设备 | C19: 频率范围：156.025MHz~162.025MHz； 信道带宽：25KHz(默认)/12.5kHz； AIS接收机灵敏度：≤-110dBm（20%误包率） 接收范围：≥2km 接口：支持RS232或RS485。 | D19: 台 | E19: 2 | G19: =ROUND(E19*F19,2) -> 0
A20: （6） | B20: 船舶超高.吃水检测计算单元 | C20: 具体技术要求： 1、处理器：单颗处理器，核心数≥20核，主频≥2.0GHz；国产自主可控； 2、内存：≥128GB DDR4，≥2666MHz； 3、硬盘：≥1块SATA SSD 960G硬盘； 4、GPU：显存≥8G，TFLOPS≥242； 5、接口：≥2个千兆网口； 6、工作温度：-10 ~ 60 °C； 6、适用于船闸运行环境，无故障运行时间不低于1万小时； 8、含功能算法，具体技术要求见设计说明书。 9、硬件5年原厂质保。 | D20: 台 | E20: 2 | G20: =ROUND(E20*F20,2) -> 0
A21: （7） | B21: 8米立杆 | C21: 含杆件、横臂、基础、接地及安装配件等 | D21: 根 | E21: 2 | G21: =ROUND(E21*F21,2) -> 0
A22: （8） | B22: 智能机箱（摄像机） | C22: 机箱规格 1.机箱尺寸（净容积） 视频监控机箱：净容积不低于 高 600×宽 500×深 250（mm） 2.机箱材质：不低于1.2mm厚镀锌钢板，机箱表面静电喷塑处理 柜体参数 3.工作环境温度 -20℃～70℃ 4.智能机箱门锁：配置电子锁具，支持远程网络开锁和机械开锁功能 5.状态采集：配置有状态采集装置，能够实现电源状态、网络状态、开关门状态、温湿度和漏电等运行环境基本数据采集； 6.开门抓拍装置：内置摄像头和补光灯，具备开门抓拍功能； 7.散热：箱侧配置不少于2个120mm×120mm成品防尘散热格栅及对应温控风扇； 8.配电装置：机箱配置DIN导轨配电单元，配有微型断路器、40kA通流量单相电源防雷保护装置、接地汇流装置和2位交流电源； 基本功能 9.负载控制：提供不少于4路可控输出，每路负载电源具备独立控制和独立重启功能； 10.电力参数采集：可监测不少于4路负载电源状态，实时采集每路负载电压、电流等参数并显示在后台系统； 11.报警和定位：具备供电供网异常、漏电和箱门开启等报警功能，具备BDS定位功能； 13.机箱外壳防护：防护等级不低于IP55； 14.网络安全：具有内外网络安全隔离网闸功能； 15.数据上传：机箱采集数据能够上传省港航机箱管理系统平台； 16.5年原厂质保 | D22: 套 | E22: 2 | G22: =ROUND(E22*F22,2) -> 0
A23: （9） | B23: 工业以太网交换机（含光模块） | C23: 全网管二层工业交换机 满足国产自主可控； 千兆电口：≥5; 千兆光口（含光模块）:≥2； 交换容量：≥20G； 包转发率：≥14.88 Mpps； 工作温度：-40℃ ~ +75℃ ； 支持VLAN，支持流量控制；支持QOS，支持SNMP 网管，支持链路聚合 | D23: 台 | E23: 4 | G23: =ROUND(E23*F23,2) -> 0
A24: （10） | B24: 安装调试、附件及辅材 | C24: 包括安装、调试，相关线缆、防雷装置等附件，以及相关辅材等所有其他费用 | D24: 项 | E24: 1 | G24: =ROUND(E24*F24,2) -> 0
A25: 2.1.1.2 | B25: 船名船号、数量识别设备
A26: （1） | B26: 检测相机 | C26: 具体技术要求： 1、不低于400万像素； 2、宽动态：不低于120 dB； 3、最低照度：彩色模式：≤0.0005lx，黑白模式：≤0.0001lx； 4、传感器类型：不小于1/1.8英寸CMOS； 5、焦距：不小于2.8~12 mm，拍摄距离满足本项目检测距离需求； 6、补光：混光（红外+暖白），不低于4颗灯珠，补光距离不小于50m，具备补光自适应功能； 7、视频压缩标准：H.265/H.264/MJPEG； 8、网络：具备RJ45 10 M/100 M/1000 M自适应以太网口、RS-485接口； 9、报警：具备掉线、遮挡报警等功能，提供SDK包二次开发使用； 10、报警信号联动：不少于3路输入、2路输出； 11、具有独立的IP地址，可以直接接入以太网络，并可以通过客户端自动搜索IP地址； 12、供电方式：支持DC12V/PoE供电，具备防反接保护； 13、功能：内置GPU，具备防抖、降噪、加热、除湿等功能，具备防雷、防浪涌保护； 14、工作温湿度：温度不低于-30 °C~60 °C，湿度不低于5%~95%@40℃，无凝结； 15、防护：不低于IP66； 16、含接地、安装支架等配套设备。 17、含五年原厂质保 | D26: 台 | E26: 2 | G26: =ROUND(E26*F26,2) -> 0
A27: （2） | B27: 抓拍相机 | C27: 具体技术要求： 1、不低于800万像素； 2、采用不小于1英寸CMOS； 3、视频采用H.265、H.264或MJPEG编码； 4、图像控制：曝光速度、AGC控制、白平衡方式控制等； 5、压缩输出码率：不低于32 Kbps~16 Mbps； 6、镜头规格：25mm，拍摄距离满足本项目抓拍距离需求； 7、快门速度是 50us到9000us； 8、光圈类型：自动光圈或手动光圈（支持远程调节）； 9、触发输出：不少于4路F+/F-输出接口，作为补光灯同步输出控制； 10、触发输入：不少于1路触发/报警输入； 11、补光：暖白光，不低于3颗灯珠，补光距离不小于40米；具备补光自适应功能； 12、功能：内置GPU，具备防抖、降噪、加热、除湿等功能，具备防雷、防浪涌保护； 13、通讯接口：具备RJ45 10 M/100 M/1000 M自适应以太网口、RS-485接口； 14、报警：具备掉线、遮挡报警等功能，提供SDK包二次开发使用； 15、具有独立的IP地址，可以直接接入以太网络，并可以通过客户端自动搜索IP地址； 16、工作温湿度：温度不低于-30 °C~70 °C，湿度不低于5%~95%@40℃，无凝结； 17、防护：不低于IP66； 18、含接地、安装支架等配套设备； 19、五年原厂质保 | D27: 台 | E27: 4 | G27: =ROUND(E27*F27,2) -> 0
A28: （3） | B28: 船舶身份.数量识别计算单元 | C28: 具体技术要求： 1、处理器：单颗处理器，核心数≥8核，主频≥2.2GHz，并与算法匹配；国产自主可控； 2、内存：≥32GB DDR4； 3、硬盘：存储≥512G； 4、GPU：显存≥8GB，AI算力 ≥100 TOPS INT8； 5、接口：≥4个千兆自适应以太网口； 6、工作温度：-10℃~60℃； 7、适用于船闸运行环境，无故障运行时间不低于1万小时； 8、含功能算法，具体技术要求见设计说明书。 9、硬件5年原厂质保。 | D28: 套 | E28: 1 | G28: =ROUND(E28*F28,2) -> 0
A29: （4） | B29: 补光灯 | C29: 具体技术要求： 1、灯珠：不少于24颗LED光源； 2、补光方式：支持LED频闪、LED爆闪、白光气体爆闪及红外气体爆闪四种补光方式； 3、光源波长：混合光源（红外+暖白光）； 4、发光角度：满足相机实际使用需求； 5、最佳投射距离：不低于20米，满足实际抓拍补光要求； 6、亮度调节： 自动控制； 7、工作环境温度：不低于-30℃ - 60℃； 8、工作环境湿度：湿度小于95%，无凝结； 9、外壳材质：金属铝； 10、防护等级：不低于IP66； 11、安装方式：万向节等安装方式，含安装支架等辅材。 | D29: 台 | E29: 4 | G29: =ROUND(E29*F29,2) -> 0
A30: （5） | B30: AIS接收设备 | C30: 频率范围：156.025MHz~162.025MHz； 信道带宽：25KHz(默认)/12.5kHz； AIS接收机灵敏度：≤-110dBm（20%误包率） 接收范围：≥2km 接口：支持RS232或RS485。 | D30: 台 | E30: 1 | G30: =ROUND(E30*F30,2) -> 0
A31: （6） | B31: 工业以太网交换机（含光模块） | C31: 全网管二层工业交换机 满足国产自主可控； 千兆电口：≥5; 千兆光口（含光模块）:≥2； 交换容量：≥20G； 包转发率：≥14.88 Mpps； 工作温度：-40℃ ~ +75℃ ； 支持VLAN，支持流量控制；支持QOS，支持SNMP 网管，支持链路聚合 | D31: 台 | E31: 8 | G31: =ROUND(E31*F31,2) -> 0
A32: （7） | B32: 6.5米立杆 | C32: 含杆件、横臂、基础、接地及安装配件等 | D32: 根 | E32: 2 | G32: =ROUND(E32*F32,2) -> 0
A33: （8） | B33: 8米立杆 | C33: 含杆件、横臂、基础、接地及安装配件等 | D33: 根 | E33: 2 | G33: =ROUND(E33*F33,2) -> 0
A34: （9） | B34: 智能机箱（摄像机） | C34: 机箱规格 1.机箱尺寸（净容积） 视频监控机箱：净容积不低于 高 600×宽 500×深 250（mm） 2.机箱材质：不低于1.2mm厚镀锌钢板，机箱表面静电喷塑处理 柜体参数 3.工作环境温度 -20℃～70℃ 4.智能机箱门锁：配置电子锁具，支持远程网络开锁和机械开锁功能 5.状态采集：配置有状态采集装置，能够实现电源状态、网络状态、开关门状态、温湿度和漏电等运行环境基本数据采集； 6.开门抓拍装置：内置摄像头和补光灯，具备开门抓拍功能； 7.散热：箱侧配置不少于2个120mm×120mm成品防尘散热格栅及对应温控风扇； 8.配电装置：机箱配置DIN导轨配电单元，配有微型断路器、40kA通流量单相电源防雷保护装置、接地汇流装置和2位交流电源； 基本功能 9.负载控制：提供不少于4路可控输出，每路负载电源具备独立控制和独立重启功能； 10.电力参数采集：可监测不少于4路负载电源状态，实时采集每路负载电压、电流等参数并显示在后台系统； 11.报警和定位：具备供电供网异常、漏电和箱门开启等报警功能，具备BDS定位功能； 13.机箱外壳防护：防护等级不低于IP55； 14.网络安全：具有内外网络安全隔离网闸功能； 15.数据上传：机箱采集数据能够上传省港航机箱管理系统平台； 16.5年原厂质保 | D34: 套 | E34: 4 | G34: =ROUND(E34*F34,2) -> 0
A35: （10） | B35: 安装调试、附件及辅材 | C35: 包括安装、调试，相关线缆、防雷装置等附件，以及相关辅材等所有其他费用 | D35: 项 | E35: 1 | G35: =ROUND(E35*F35,2) -> 0
A36: 2.1.1.3 | B36: 系缆安全监测设备 | C36: 实现对闸室内首尾档船舶的系换缆识别
A37: （1） | B37: 系缆检测枪机 | C37: 具体技术要求： 1、双通道相机，通道1不低于800万像素，通道2不低于400万像素； 2、宽动态：不低于120 dB； 3、最低照度：通道1：0.001lux（彩色模式）；0.0001lux（黑白模式）；通道2：0.002lux（彩色模式）；0.0002lux（黑白模式）； 4、传感器类型：通道1：不小于1/1.8英寸 CMOS；通道2：不小于1/2.5英寸CMOS； 5、焦距：通道1：不小于10~50mm；通道2：不小于3.6mm；拍摄距离满足本项目检测距离需求； 6、补光：通道1：混合补光，不低于5颗灯珠，补光距离不小于80m；通道2：混合补光，补光距离不小于30m；具备补光自适应功能； 7、视频压缩标准：H.265/H.264/MJPEG； 8、网络：具备RJ45 10 M/100 M/1000 M自适应以太网口、RS-485接口； 9、报警：具备掉线、遮挡报警等功能，提供SDK包开发使用； 10、报警信号联动：不少于3路输入、2路输出； 11、具有独立的IP地址，可以直接接入以太网络，并可以通过客户端自动搜索IP地址； 12、报警信号联动：具备报警输入、输出； 13、工作温湿度：温度不低于-30 °C~60 °C，湿度不低于5%~95%@40℃，无凝结； 14、防护：不低于IP66； 15、含接地、安装支架等配套设备。 16、五年原厂质保 | D37: 台 | E37: 4 | G37: =ROUND(E37*F37,2) -> 0
A38: （2） | B38: 6.5米立杆 | C38: 含杆件、横臂、基础、接地及安装配件等 | D38: 根 | E38: 4 | G38: =ROUND(E38*F38,2) -> 0
A39: （3） | B39: 系换缆状态监测计算单元 | C39: 具体技术要求： 1、处理器：单颗处理器，核心数≥8核，主频≥2.2GHz，并与算法匹配；国产自主可控； 2、内存：≥32GB DDR4； 3、硬盘：存储≥512G； 4、GPU：显存≥8GB，AI算力 ≥100 TOPS INT8； 5、接口：≥4个千兆自适应以太网口； 6、工作温度：-10℃~60℃； 7、适用于船闸运行环境，无故障运行时间不低于1万小时； 8、含功能算法，具体技术要求见设计说明书。 9、硬件5年原厂质保。 | D39: 套 | E39: 1 | G39: =ROUND(E39*F39,2) -> 0
A40: （4） | B40: 安装调试、附件及辅材 | C40: 包括安装、调试，相关线缆、防雷装置等附件，以及相关辅材等所有其他费用 | D40: 项 | E40: 1 | G40: =ROUND(E40*F40,2) -> 0
...
