Workbook

Sheet 投资汇总表
A1: 光储充电站投资预算汇总表
A2: 单位：元
A3: 序号 | B3: 分项 | C3: 合价
A4: 1 | B4: 光伏发电部分 | C4: =投资汇总表!I20 -> 149910
A5: 2 | B5: 储能部分 | C5: =投资汇总表!I28 -> 150737
A6: 3 | B6: 充电桩部分 | C6: =投资汇总表!I34 -> 4131.2
A7: 4 | B7: 钢构及接地部分 | C7: =投资汇总表!I39 -> 270160
A8: 合计： | C8: =SUM(C4:C7) -> 574938.2
A10: 主要设备投资预算表
A11: 设备名称 | B11: 规格、型号 | C11: 单位 | D11: 数量 | E11: 材料单价 | F11: 材料合价 | G11: 安装单价 | H11: 安装合价 | I11: 单项合价 | J11: 备注
A12: 一、光伏发电部分
A13: 单晶光伏组件 | B13: 350W，多主栅PERC半片组件，1689*996*35,6*20，20.8% | C13: 块 | D13: 126 | E13: =2*350 -> 700 | F13: =D13*E13 -> 88200 | G13: 60 | H13: =D13*G13 -> 7560 | I13: =F13+H13 -> 95760
A14: 光伏支架 | B14: 铝合金，含导轨、夹具、压块 | C14: 套 | D14: 1 | E14: =0.4*44100 -> 17640 | F14: =D14*E14 -> 17640 | G14: 6200 | H14: =D14*G14 -> 6200 | I14: =F14+H14 -> 23840
A15: 逆变器 | B15: EA25KTSI,组串式逆变器 | C15: 台 | D15: 2 | E15: 8300 | F15: =D15*E15 -> 16600 | G15: 200 | H15: =D15*G15 -> 400 | I15: =F15+H15 -> 17000
A16: 光伏电缆 | B16: PF-1*4mm | C16: 米 | D16: 800 | E16: 3 | F16: =D16*E16 -> 2400 | G16: 1.5 | H16: =D16*G16 -> 1200 | I16: =F16+H16 -> 3600
A17: 电力电缆 | B17: ZR-YJV-0.6/1KV-4*25+1*16mm | C17: 米 | D17: 100 | E17: 46 | F17: =D17*E17 -> 4600 | G17: 4 | H17: =D17*G17 -> 400 | I17: =F17+H17 -> 5000
A18: 组串引出线接插件 | B18: MC4 | C18: 套 | D18: 40 | E18: 5 | F18: =D18*E18 -> 200 | G18: 4 | H18: =D18*G18 -> 160 | I18: =F18+H18 -> 360
A19: 并网柜 | B19: 50KW，详见图纸 | C19: 台 | D19: 1 | E19: 3850 | F19: =D19*E19 -> 3850 | G19: 500 | H19: =D19*G19 -> 500 | I19: =F19+H19 -> 4350
A20: 小计 | I20: =SUM(I13:I19) -> 149910
A21: 二、储能部分
A22: 储能变流器 | B22: EAPCS 50K | C22: 台 | D22: 1 | E22: 16525 | F22: =D22*E22 -> 16525 | G22: 260 | H22: =D22*G22 -> 260 | I22: =F22+H22 -> 16785
A23: 磷酸铁锂电池 | B23: 3.2V/50Ah | C23: KWH | D23: 76.8 | E23: 1380 | F23: =D23*E23 -> 105984 | G23: 10 | H23: =D23*G23 -> 768 | I23: =F23+H23 -> 106752
A24: 电池柜 | B24: 535*670*2200，带直流开关 | C24: 台 | D24: 1 | E24: 2800 | F24: =D24*E24 -> 2800 | G24: 100 | H24: =D24*G24 -> 100 | I24: =F24+H24 -> 2900
A25: 电池连接线 | C25: 套 | D25: 1 | E25: 1600 | F25: =D25*E25 -> 1600 | G25: 300 | H25: =D25*G25 -> 300 | I25: =F25+H25 -> 1900
A26: EMS能量管理系统 | B26: 定制 | C26: 套 | D26: 1 | E26: 20000 | F26: =D26*E26 -> 20000 | H26: =D26*G26 -> 0 | I26: =F26+H26 -> 20000
A27: 储能交流电缆 | B27: ZR-YJV-0.6/1KV-4*25+1*16m | C27: 米 | D27: 30 | E27: 75 | F27: =D27*E27 -> 2250 | G27: 5 | H27: =D27*G27 -> 150 | I27: =F27+H27 -> 2400
A28: 小计 | I28: =SUM(I22:I27) -> 150737
A29: 三、充电桩部分
A30: 充电桩 | B30: 7KVA，单枪，立式充电桩 | C30: 台 | D30: 1 | E30: 3126.2 | F30: =D30*E30 -> 3126.2 | G30: 180 | H30: =D30*G30 -> 180 | I30: =F30+H30 -> 3306.2
A31: 发卡机 | C31: 台 | D31: 1 | E31: 300 | F31: =D31*E31 -> 300 | G31: 55 | H31: =D31*G31 -> 55 | I31: =F31+H31 -> 355
A32: 充电卡 | C32: 张 | D32: 5 | E32: 10 | F32: =D32*E32 -> 50 | G32: 0 | H32: =D32*G32 -> 0 | I32: =F32+H32 -> 50
A33: 电力电缆 | B33: 1*10 | C33: 米 | D33: 60 | E33: 5 | F33: =D33*E33 -> 300 | G33: 2 | H33: =D33*G33 -> 120 | I33: =F33+H33 -> 420
A34: 小计 | I34: =SUM(I30:I33) -> 4131.2
A35: 四、钢构及接地部分
A36: 钢结构 | B36: 预估价，含梁、柱、屋面等材料 | C36: 平方米 | D36: =15*16 -> 240 | E36: 700 | F36: =D36*E36 -> 168000 | G36: 400 | H36: =D36*G36 -> 96000 | I36: =F36+H36 -> 264000
A37: 接地扁钢 | B37: 40*4 Q235B | C37: 米 | D37: 320 | E37: 12 | F37: =D37*E37 -> 3840 | G37: 5 | H37: =D37*G37 -> 1600 | I37: =F37+H37 -> 5440
A38: 接地线 | B38: φ16圆钢 L=1.5M | C38: 米 | D38: 60 | E38: 8 | F38: =D38*E38 -> 480 | G38: 4 | H38: =D38*G38 -> 240 | I38: =F38+H38 -> 720
A39: 小计 | I39: =SUM(I36:I38) -> 270160
A43: 年均发电量测算表
A44: 项目名称 | B44: 年平均 | C44: 合计 | D44: 第1年 | E44: 第2年 | F44: 第3年 | G44: 第4年 | H44: 第5年 | I44: 第6年 | J44: 第7年 | K44: 第8年 | L44: 第9年 | M44: 第10年 | N44: 第11年 | O44: 第12年 | P44: 第13年
...
